<?xml version="1.0" encoding="utf-8"?>
<!-- This URDF was automatically created by SolidWorks to URDF Exporter! Originally created by Stephen Brawner (brawner@gmail.com) 
     Commit Version: 1.6.0-1-g15f4949  Build Version: 1.6.7594.29634
     For more information, please see http://wiki.ros.org/sw_urdf_exporter -->
<robot
  name="servo_urdf">
  <link
    name="base_link">
    <inertial>
      <origin
        xyz="0.006 0.013643 0.011736"
        rpy="0 0 0" />
      <mass
        value="0.0075811" />
      <inertia
        ixx="8.2381E-07"
        ixy="2.0055E-23"
        ixz="5.0317E-24"
        iyy="4.4654E-07"
        iyz="-2.5205E-08"
        izz="5.558E-07" />
    </inertial>
    <visual>
      <origin
        xyz="0 0 0"
        rpy="0 0 0" />
      <geometry>
        <mesh
          filename="package://servo_urdf/meshes/base_link.STL" />
      </geometry>
      <material
        name="">
        <color
          rgba="0.79216 0.81961 0.93333 1" />
      </material>
    </visual>
    <collision>
      <origin
        xyz="0 0 0"
        rpy="0 0 0" />
      <geometry>
        <mesh
          filename="package://servo_urdf/meshes/base_link.STL" />
      </geometry>
    </collision>
  </link>
  <link
    name="puntero">
    <inertial>
      <origin
        xyz="0 0.0039611 0.006426"
        rpy="0 0 0" />
      <mass
        value="0.00088336" />
      <inertia
        ixx="4.9735E-08"
        ixy="-7.1667E-26"
        ixz="-8.3799E-25"
        iyy="5.1472E-08"
        iyz="-2.2057E-10"
        izz="7.0214E-09" />
    </inertial>
    <visual>
      <origin
        xyz="0 0 0"
        rpy="0 0 0" />
      <geometry>
        <mesh
          filename="package://servo_urdf/meshes/puntero.STL" />
      </geometry>
      <material
        name="">
        <color
          rgba="0.79216 0.81961 0.93333 1" />
      </material>
    </visual>
    <collision>
      <origin
        xyz="0 0 0"
        rpy="0 0 0" />
      <geometry>
        <mesh
          filename="package://servo_urdf/meshes/puntero.STL" />
      </geometry>
    </collision>
  </link>
  <joint
    name="junta"
    type="continuous">
    <origin
      xyz="0.006 0.0295 0.017406"
      rpy="0 0 0" />
    <parent
      link="base_link" />
    <child
      link="puntero" />
    <axis
      xyz="0 1 0" />
  </joint>
</robot>